<?xml version="1.0"?>
<robot name="turtle">
    <link name="base_link">
        <visual>
            <geometry>
                <box size="0.6 0.3 0.3" />
            </geometry>
            <material name="paint">
                <color rgba="0.5 0.5 0.7 1.0" />
            </material>
        </visual>
    </link>

    <link name="front_caster">
        <visual>
            <geometry>
                <box size="0.1 0.1 0.3" />
            </geometry>
            <material name="paint" />
        </visual>
    </link>

    <joint name="front_caster_joint" type="continuous">
        <axis xyz="0 0 1" />
        <parent link="base_link" />
        <child link="front_caster" />
        <origin rpy="0 0 0" xyz="0.3 0 0" />
    </joint>

    <link name="front_wheel">
        <visual>
            <geometry>
                <cylinder length="0.05" radius="0.035" />
            </geometry>
            <material name="black">
                <color rgba="0.1 0.1 0.1 1" />
            </material>
        </visual>
    </link>

    <joint name="front_wheel_joint" type="continuous">
        <axis xyz="0 0 1" />
        <parent link="front_caster" />
        <child link="front_wheel" />
        <origin rpy="-1.5708 0 0" xyz="0.05 0 -0.15" />
    </joint>


    <link name="right_wheel">
        <visual>
            <geometry>
                <cylinder length="0.05" radius="0.035" />
            </geometry>
            <material name="black" />
        </visual>
    </link>

    <joint name="right_wheel_joint" type="continuous">
        <axis xyz="0 0 1" />
        <parent link="base_link" />
        <child link="right_wheel" />
        <origin rpy="-1.5708 0 0" xyz="-0.2825 -0.125 -0.15" />
    </joint>

    <link name="left_wheel">
        <visual>
            <geometry>
                <cylinder length="0.05" radius="0.035" />
            </geometry>
            <material name="black" />
        </visual>
    </link>

    <joint name="left_wheel_joint" type="continuous">
        <axis xyz="0 0 1" />
        <parent link="base_link" />
        <child link="left_wheel" />
        <origin rpy="-1.5708 0 0" xyz="-0.2825 0.125 -0.15" />
    </joint>
</robot>